Workbook

Sheet Read me
A1: WorkSwarm usability findings — reviewed and re-categorised
A3: Source | B3: allfindings.xlsx — 108 findings across 3 sheets, 9 personas, 41 concerns.
A4: Reviewed | B4: 2026-09-10, against openJiuwen-ai/jiuwenswarm @ develop 2026-09-05 (0.2.5.beta1) and agent-core 0.1.17.
A5: What changed | B5: Every finding keeps its original text. Added: a 4-role / 8-theme taxonomy, a verdict, evidence, competitor position, and impact/effort/priority.
A6: Rows added | B6: 7 findings from the WorkBuddy competitive review had no equivalent row in the source sheet and are appended as #109-#115. The Source column marks them; filter it to separate them from the original 108.
A7: Not carried over | B7: W6 (spend/budget) is already the COST group, W8 (English parity) is #39/#61/#62, and W9/W10 are portal and marketing copy rather than product findings - see the WorkBuddy response doc for those.
A9: ADDED ROWS — what they are
A10: #109 (W0) | B10: The rename has broken every public install path. pip install jiuwenswarm resolves to 0.2.3 from July; the portal's workswarm-tui is a 404.
A11: #110 (W1) | B11: A zero-key first run already ships (Opencode Zen free models, on by default) but is undocumented and the README states the opposite.
A12: #111 (W2) | B12: jiuwenbox sandbox is opt-in and setup never asks which folders it may use. Distinct from #25, which is the approval policy.
A13: #112 (W3) | B13: Community skills install with no security audit. Distinct from #94, which is ratings and freshness rather than a security scan.
A14: #113 (W4) | B14: The 26 built-in skills are Huawei engineering tools; roughly four suit the office user the product claims.
A15: #114 (W5) | B15: The catalogue accepts only its own hub although skills are already SKILL.md. Distinct from #42, which is cross-instance sharing.
A16: #115 (W7) | B16: Cluster mode is the README default, so a new user's first task takes the slowest and most expensive path.
A18: METHOD — verdicts
A19: Confirmed | B19: Checked against the tree, or a direct restatement of a defect verified elsewhere in this review. Evidence column names the file where one exists.
A20: Confirmed (duplicate) | B20: Real, but the same defect as another row. See the Dup group column — 10 rows collapse into 6 issues.
A21: Partly true | B21: The problem is real but narrower than written; partial support already exists. Fixing the stated version would over-build.
A22: Overstated | B22: The capability largely exists. The finding would send someone to build something already shipped.
A23: Asserted - not re-verified | B23: Plausible and internally consistent, but not independently checked in this pass. Mostly agent-core SDK documentation claims.
A25: METHOD — competitors
A26: Sources | B26: WorkBuddy: Tencent product pages + third-party reviews (no public source). OpenClaw: docs.openclaw.ai + release notes. Hermes: NousResearch/hermes-agent docs. Treat WorkBuddy detail as approximate.
A27: Behind | B27: One or more competitors ship this and market it. Absence is a comparison loss.
A28: Level | B28: Nobody in the set does this well. Fixing it is quality work, not catch-up.
A29: Uncontested | B29: No competitor has it. Doing it is a differentiator, not table stakes.
A31: METHOD — scoring
A32: Impact 1-5 | B32: 5 = decides an evaluation or blocks adoption. 3 = visible friction. 1 = polish.
A33: Effort S/M/L | B33: S = under a day. M = days. L = a sprint or more.
A34: Priority | B34: P0 ship now · P1 next minor · P2 backlog · P3 nice to have. Set from impact x effort, then adjusted for competitive posture.
A36: WHY THE PERSONAS WERE REPLACED
A37: The problem | B37: Four of the nine personas — Shared, Web User, Web Chat, Web Code — are UI surfaces, not people. Self-hoster, Bot-hoster and Web User are the same person on different days. 41 concerns is more categories than a team can hold.
A38: The fix | B38: Two axes instead of one. ROLE answers who is blocked; THEME answers what kind of work fixes it. A finding has exactly one of each.
A40: ROLES (4)
A41: Operator | B41: Installs it, configures it, runs it, keeps it alive. Was: Self-hoster, Bot-hoster.
A42: End user | B42: Does actual work inside the product. Was: Web User, Web Chat, Web Code, most of Shared.
A43: Extender | B43: Adds capability inside it — rails, skills, channels, plugins. Was: Engine Contributor, Skill Author.
A44: Integrator | B44: Builds a separate application on top of it, over the API. Was: Product Builder.
A46: THEMES (8)
A47: 1 Get it running | B47: Install, config, credentials, first run, ports, upgrade, diagnostics.
A48: 2 Trust & control | B48: Permissions, sandbox, approvals, undo, identity, privacy, blast radius.
...

Sheet Findings
A1: ID | B1: Role | C1: Theme | D1: Source | E1: Finding | F1: Verdict | G1: Evidence / note | H1: Dup group | I1: Impact | J1: Effort | K1: Priority | L1: Posture | M1: WorkBuddy | N1: OpenClaw | O1: Hermes | P1: Orig sheet | Q1: Orig persona | R1: Orig concern
A2: 1 | B2: Extender | C2: 7 Extend it | D2: Original sheet | E2: No stable public API or semantic-versioning contract | F2: Asserted - not re-verified | G2: agent-core imported from git SHA; both pkgs 0.x | I2: 4 | J2: M | K2: P1 | L2: Behind | M2: Closed source | N2: Documents plugin API + versioned docs | O2: Documents plugin API + versioned docs | P2: Contributors | Q2: Engine Contributor | R2: Extension Documentation & Stability
A3: 2 | B3: Extender | C3: 7 Extend it | D3: Original sheet | E3: The examples directory is undiscoverable and inconsistent | F3: Partly true | G3: examples/ does exist (examples/harness/*); issue is index+consistency, not absence | I3: 3 | J3: M | K3: P2 | L3: Behind | M3: Closed | N3: Plugin examples in docs | O3: Skill/plugin examples | P3: Contributors | Q3: Engine Contributor | R3: Extension Documentation & Stability
A4: 3 | B4: Extender | C4: 7 Extend it | D4: Original sheet | E4: Adding prompt content from a rail is an undocumented hidden API | F4: Asserted - not re-verified | G4: system_prompt_builder.add_section priority model undocumented | I4: 4 | J4: S | K4: P1 | L4: Behind | M4: Closed | N4: Hooks doc names each event | O4: pre_llm_call documented w/ ctx.register_hook() | P4: Contributors | Q4: Engine Contributor | R4: Rails & Context API
A5: 4 | B5: Extender | C5: 7 Extend it | D5: Original sheet | E5: Rail hook execution order can only be learned from source | F5: Asserted - not re-verified | G5: rail hook order + priority semantics only in source | I5: 4 | J5: S | K5: P1 | L5: Behind | M5: Closed | N5: Event hooks doc lists firing order | O5: Hook order documented | P5: Contributors | Q5: Engine Contributor | R5: Rails & Context API
A6: 5 | B6: Extender | C6: 7 Extend it | D6: Original sheet | E6: The hook context object is undocumented and untyped | F6: Asserted - not re-verified | G6: AgentCallbackContext fields/mutability undocumented | I6: 3 | J6: M | K6: P2 | L6: Behind | M6: Closed | N6: ctx documented | O6: ctx documented | P6: Contributors | Q6: Engine Contributor | R6: Rails & Context API
A7: 6 | B7: Extender | C7: 7 Extend it | D7: Original sheet | E7: The rail extension API has no public documentation | F7: Confirmed | G7: AgentRail 10 hooks + DeepAgentRail +2, no public reference page; only Chinese docs | I7: 5 | J7: M | K7: P0 | L7: Behind | M7: Closed | N7: Public plugin/hooks reference | O7: Public plugin/hooks reference | P7: Contributors | Q7: Engine Contributor | R7: Rails & Context API
A8: 7 | B8: Extender | C8: 7 Extend it | D8: Original sheet | E8: The structured error API isn't documented for rail authors | F8: Asserted - not re-verified | G8: raise_error framework undiscoverable; plain exceptions lose recoverable/fatal/code | I8: 3 | J8: S | K8: P2 | L8: Level | M8: Closed | N8: — | O8: — | P8: Contributors | Q8: Engine Contributor | R8: Rails & Context API
A9: 8 | B9: Extender | C9: 7 Extend it | D9: Original sheet | E9: No CLI to scaffold a new rail or skill | F9: Confirmed | G9: no scaffold CLI in pyproject scripts | I9: 3 | J9: M | K9: P2 | L9: Behind | M9: skill-creator (no-code) | N9: Plugin scaffold | O9: hermes skill create | P9: Contributors | Q9: Engine Contributor | R9: Extension Testing & Tooling
A10: 9 | B10: Extender | C10: 7 Extend it | D10: Original sheet | E10: No integration test layer between unit tests and a full system | F10: Asserted - not re-verified | G10: only mocked unit tests + full e2e | I10: 3 | J10: L | K10: P3 | L10: Level | M10: — | N10: — | O10: — | P10: Contributors | Q10: Engine Contributor | R10: Extension Testing & Tooling
A11: 10 | B11: Extender | C11: 7 Extend it | D11: Original sheet | E11: Writing a rail test requires reverse-engineering mock infrastructure | F11: Asserted - not re-verified | G11: MockLLMModel + _make_agent private/undocumented | I11: 2 | J11: S | K11: P2 | L11: Level | M11: — | N11: — | O11: — | P11: Contributors | Q11: Engine Contributor | R11: Extension Testing & Tooling
A12: 11 | B12: Extender | C12: 7 Extend it | D12: Original sheet | E12: Registering tools from a rail has no developer guide | F12: Asserted - not re-verified | G12: ability_manager.add(ToolCard) only visible in a test file | I12: 4 | J12: S | K12: P1 | L12: Behind | M12: Closed | N12: Tool registration documented | O12: 40+ tools, toolset docs | P12: Contributors | Q12: Engine Contributor | R12: Tools & Agent Factory
A13: 12 | B13: Extender | C13: 7 Extend it | D13: Original sheet | E13: The agent factory has too many undocumented parameters | F13: Confirmed | G13: create_deep_agent has 15+ params (factory.py:455); no param docs | I13: 4 | J13: S | K13: P1 | L13: Behind | M13: Closed | N13: — | O13: — | P13: Contributors | Q13: Engine Contributor | R13: Tools & Agent Factory
... A17: 16 | B17: Operator | C17: 2 Trust & control | D17: Original sheet | E17: Data is kept indefinitely with no expiry controls | F17: Confirmed | G17: only trajectory_ui.retention_days exists; no conversation/memory expiry | I17: 3 | J17: M | K17: P2 | L17: Behind | M17: Cloud retention policy | N17: SQLite sessions + archiving | O17: — | P17: Users | Q17: Self-hoster | R17: Data Retention
A18: 17 | B18: End user | C18: 3 See what happened | D18: Original sheet | E18: No hints about what is consuming the context | F18: Confirmed | G18: no breakdown of what fills the window | H18: COST | I18: 3 | J18: M | K18: P2 | L18: Behind | M18: — | N18: Context/overhead work in 2026.9.1 | O18: — | P18: Users | Q18: Self-hoster | R18: Cost & Token Economics
A19: 18 | B19: End user | C19: 3 See what happened | D19: Original sheet | E19: No visibility into token usage or session cost | F19: Partly true | G19: OVERSTATED: trajectory token-cost timeline exists; missing piece is budget+alerting | H19: COST | I19: 4 | J19: M | K19: P1 | L19: Behind | M19: Credits + 80%/90% alerts | N19: Per-session cost | O19: Cost-safe loops + session budget | P19: Users | Q19: Self-hoster | R19: Cost & Token Economics
A20: 19 | B20: Operator | C20: 3 See what happened | D20: Original sheet | E20: Trivial prompts still build the full context | F20: Asserted - not re-verified | G20: full context assembled regardless of prompt size | I20: 3 | J20: L | K20: P2 | L20: Level | M20: — | N20: Lower overhead for long conversations | O20: — | P20: Users | Q20: Self-hoster | R20: Cost & Token Economics
A21: 20 | B21: Operator | C21: 5 Find your way | D21: Original sheet | E21: Documentation is scattered with no guide for common tasks | F21: Confirmed | G21: docs split across YAML comments, /docs, SKILL.md; no task-oriented guide | I21: 3 | J21: M | K21: P2 | L21: Behind | M21: — | N21: Task-oriented docs site | O21: Task-oriented docs site | P21: Users | Q21: Self-hoster | R21: Running & Managing the Instance
A22: 21 | B22: Operator | C22: 6 Reach & inclusion | D22: Original sheet | E22: Logs and config mix languages unpredictably | F22: Confirmed | G22: VERIFIED: config.yaml comments alternate zh/en mid-section | I22: 3 | J22: M | K22: P2 | L22: Behind | M22: — | N22: — | O22: — | P22: Users | Q22: Self-hoster | R22: Running & Managing the Instance
A23: 22 | B23: Operator | C23: 1 Get it running | D23: Original sheet | E23: No visibility into which ports and URLs are in use | F23: Confirmed | G23: no port/URL echo after start; silent port fallback | I23: 4 | J23: S | K23: P1 | L23: Behind | M23: — | N23: Prints gateway URL + health | O23: Prints REPL/gateway target | P23: Users | Q23: Self-hoster | R23: Running & Managing the Instance
A24: 23 | B24: Operator | C24: 2 Trust & control | D24: Original sheet | E24: Permission rules can only be edited in raw YAML | F24: Confirmed | G24: tiered policy is regex YAML only; dialog shows generic 'full access' | I24: 4 | J24: M | K24: P1 | L24: Behind | M24: — | N24: Permission scoping in Control UI | O24: — | P24: Users | Q24: Self-hoster | R24: Running & Managing the Instance
A25: 24 | B25: Operator | C25: 1 Get it running | D25: Original sheet | E25: Upgrading can silently break an existing config | F25: Partly true | G25: OVERSTATED: config_version (config.yaml:3) and migrate_config_from_template() both exist; what's missing is a breaking-change changelog | I25: 3 | J25: S | K25: P2 | L25: Level | M25: — | N25: Migration on 2.0 upgrade | O25: — | P25: Users | Q25: Self-hoster | R25: Running & Managing the Instance
A26: 25 | B26: Operator | C26: 2 Trust & control | D26: Original sheet | E26: Default permissions are off, contradicting the README | F26: Confirmed | G26: VERIFIED: permissions.enabled:false in all 3 templates; README:158 says the opposite | I26: 5 | J26: S | K26: P0 | L26: Behind | M26: Sandbox+approval on by default | N26: Ask-first chosen at onboarding | O26: Approval engine on | P26: Users | Q26: Self-hoster | R26: Running & Managing the Instance
A27: 26 | B27: Operator | C27: 2 Trust & control | D27: Original sheet | E27: Granted permissions are invisible once granted | F27: Confirmed | G27: approval_overrides has no in-UI ledger | I27: 3 | J27: M | K27: P2 | L27: Behind | M27: — | N27: Permission scoping visible | O27: — | P27: Users | Q27: Self-hoster | R27: Running & Managing the Instance
A28: 27 | B28: Operator | C28: 1 Get it running | D28: Original sheet | E28: Missing optional extras fail when used, not at startup | F28: Confirmed | G28: VERIFIED: no extras check in start_services.py | I28: 3 | J28: S | K28: P2 | L28: Level | M28: — | N28: Health check at onboarding | O28: Single binary - N/A | P28: Users | Q28: Self-hoster | R28: Startup & Configuration
A29: 28 | B29: Operator | C29: 1 Get it running | D29: Original sheet | E29: Setup ends before credentials are tested | F29: Confirmed | G29: ModelSetupGuide tour ends at the models panel | H29: SETUP | I29: 5 | J29: M | K29: P0 | L29: Behind | M29: Bundled model, nothing to test | N29: Blocks until a live completion succeeds | O29: hermes setup validates | P29: Users | Q29: Self-hoster | R29: Startup & Configuration
A30: 29 | B30: Operator | C30: 1 Get it running | D30: Original sheet | E30: The config file has no validation or check tool | F30: Confirmed | G30: one file: models+memory+channels+permissions+observability+SSH; undocumented ${VAR:-default} | I30: 4 | J30: M | K30: P1 | L30: Behind | M30: — | N30: Config written by onboarding | O30: YAML+env merge, wizard-driven | P30: Users | Q30: Self-hoster | R30: Startup & Configuration
A31: 30 | B31: Operator | C31: 1 Get it running | D31: Original sheet | E31: Wrong credentials surface only on the first chat, never at startup | F31: Confirmed (duplicate) | G31: same defect as #28 | H31: SETUP | I31: 5 | J31: M | K31: P0 | L31: Behind | M31: Bundled model | N31: Live completion gate | O31: Wizard validates | P31: Users | Q31: Self-hoster | R31: Startup & Configuration
A32: 31 | B32: Operator | C32: 1 Get it running | D32: Original sheet | E32: Headless installs silently become Chinese installs | F32: Confirmed | G32: VERIFIED: common/utils.py:536-538 returns 'zh' when stdin is not a TTY | I32: 5 | J32: S | K32: P0 | L32: Behind | M32: — | N32: --non-interactive with explicit flags | O32: Install script is locale-neutral | P32: Users | Q32: Self-hoster | R32: Startup & Configuration
A33: 32 | B33: Operator | C33: 1 Get it running | D33: Original sheet | E33: Nothing verifies the model before the first conversation | F33: Confirmed (duplicate) | G33: same defect as #28 | H33: SETUP | I33: 5 | J33: M | K33: P0 | L33: Behind | M33: Bundled model | N33: Live completion gate | O33: Wizard validates | P33: Users | Q33: Self-hoster | R33: Startup & Configuration
A34: 33 | B34: Operator | C34: 1 Get it running | D34: Original sheet | E34: No minimal starting point for config (818 keys) | F34: Confirmed | G34: VERIFIED: 1,510 lines / 818 keys / depth 8 | I34: 4 | J34: M | K34: P1 | L34: Behind | M34: — | N34: Config is not the interface | O34: Wizard + REPL cover common path | P34: Users | Q34: Self-hoster | R34: Startup & Configuration
A35: 34 | B35: Operator | C35: 1 Get it running | D35: Original sheet | E35: Running the CLI without config gives no next step | F35: Confirmed | G35: bare CLI with no config gives unclear error; --help has no first-run path | I35: 3 | J35: S | K35: P2 | L35: Behind | M35: — | N35: onboard is the entry point | O35: hermes drops into guided REPL | P35: Users | Q35: Self-hoster | R35: First Run
A36: 35 | B36: Operator | C36: 1 Get it running | D36: Original sheet | E36: Setup wizard ends before the model is confirmed working | F36: Confirmed (duplicate) | G36: same defect as #28 | H36: SETUP | I36: 5 | J36: M | K36: P0 | L36: Behind | M36: Bundled model | N36: Live completion gate | O36: Wizard validates | P36: Users | Q36: Self-hoster | R36: First Run
A37: 36 | B37: Operator | C37: 1 Get it running | D37: Original sheet | E37: You aren't told when a subsystem fails | F37: Confirmed | G37: non-critical subsystem failures are silent (memory provider, OTel, channel init) | I37: 4 | J37: M | K37: P1 | L37: Behind | M37: — | N37: Host status dashboard CPU/mem/disk/uptime | O37: — | P37: Users | Q37: Self-hoster | R37: Health & Degradation
A38: 37 | B38: End user | C38: 3 See what happened | D38: Original sheet | E38: No per-model budget dashboard | F38: Confirmed (duplicate) | G38: same need as #18 - budget layer on existing cost data | H38: COST | I38: 4 | J38: L | K38: P2 | L38: Behind | M38: Credits + 80%/90% alerts | N38: Per-session cost | O38: Session budget | P38: Users | Q38: Self-hoster | R38: Cost & Tokens
A39: 38 | B39: Operator | C39: 1 Get it running | D39: Original sheet | E39: No diagnostic ('doctor') command | F39: Confirmed | G39: VERIFIED: no doctor/diagnose entry point in pyproject scripts | H39: DOCTOR | I39: 4 | J39: M | K39: P1 | L39: Behind | M39: — | N39: Gateway health check + status dashboard | O39: Single binary removes most failure modes | P39: Users | Q39: Self-hoster | R39: Diagnostics
A40: 39 | B40: Operator | C40: 6 Reach & inclusion | D40: Original sheet | E40: English docs show the Chinese UI | F40: Confirmed | G40: VERIFIED: 55 of 144 image refs in docs/en use CJK-named screenshots | I40: 3 | J40: M | K40: P2 | L40: Behind | M40: — | N40: 20+ locales, localized docs | O40: — | P40: Users | Q40: Self-hoster | R40: Documentation
A41: 40 | B41: Operator | C41: 2 Trust & control | D41: Original sheet | E41: No login on the Web UI: local Web users share one identity | F41: Confirmed | G41: VERIFIED: no web auth; only OpenAI account-login helpers in the handler | I41: 5 | J41: L | K41: P1 | L41: Behind | M41: — | N41: User auth + permission scoping + device pairing | O41: Gateway auth | P41: Users | Q41: Bot-hoster | R41: Identity & Isolation
A42: 41 | B42: Operator | C42: 2 Trust & control | D42: Original sheet | E42: No multi-tenancy: every user shares one workspace | F42: Confirmed | G42: single-workspace; user_id is routing/logging only | I42: 5 | J42: L | K42: P1 | L42: Behind | M42: — | N42: Roles + shared cloud sessions | O42: Per-platform identity | P42: Users | Q42: Bot-hoster | R42: Identity & Isolation
A43: 42 | B43: Extender | C43: 7 Extend it | D43: Original sheet | E43: No shared skill library across instances | F43: Confirmed | G43: skills are per-workspace; no cross-instance sharing | I43: 3 | J43: M | K43: P2 | L43: Behind | M43: SkillHub + ClawHub | N43: Plugin/skill marketplace | O43: agentskills.io standard | P43: Users | Q43: Bot-hoster | R43: Shared Skill Library
...

Sheet Roll-up
A1: Findings by role x priority | H1: Counts cover all 115 rows (108 original + 7 added).
B2: P0 | C2: P1 | D2: P2 | E2: P3 | F2: Total
A3: Operator | B3: =COUNTIFS(Findings!$B$2:$B$116,$A3,Findings!$K$2:$K$116,B$2) -> 9 | C3: =COUNTIFS(Findings!$B$2:$B$116,$A3,Findings!$K$2:$K$116,C$2) -> 9 | D3: =COUNTIFS(Findings!$B$2:$B$116,$A3,Findings!$K$2:$K$116,D$2) -> 9 | E3: =COUNTIFS(Findings!$B$2:$B$116,$A3,Findings!$K$2:$K$116,E$2) -> 0 | F3: =SUM(B3:E3) -> 27
A4: End user | B4: =COUNTIFS(Findings!$B$2:$B$116,$A4,Findings!$K$2:$K$116,B$2) -> 4 | C4: =COUNTIFS(Findings!$B$2:$B$116,$A4,Findings!$K$2:$K$116,C$2) -> 19 | D4: =COUNTIFS(Findings!$B$2:$B$116,$A4,Findings!$K$2:$K$116,D$2) -> 18 | E4: =COUNTIFS(Findings!$B$2:$B$116,$A4,Findings!$K$2:$K$116,E$2) -> 11 | F4: =SUM(B4:E4) -> 52
A5: Extender | B5: =COUNTIFS(Findings!$B$2:$B$116,$A5,Findings!$K$2:$K$116,B$2) -> 3 | C5: =COUNTIFS(Findings!$B$2:$B$116,$A5,Findings!$K$2:$K$116,C$2) -> 11 | D5: =COUNTIFS(Findings!$B$2:$B$116,$A5,Findings!$K$2:$K$116,D$2) -> 9 | E5: =COUNTIFS(Findings!$B$2:$B$116,$A5,Findings!$K$2:$K$116,E$2) -> 2 | F5: =SUM(B5:E5) -> 25
A6: Integrator | B6: =COUNTIFS(Findings!$B$2:$B$116,$A6,Findings!$K$2:$K$116,B$2) -> 2 | C6: =COUNTIFS(Findings!$B$2:$B$116,$A6,Findings!$K$2:$K$116,C$2) -> 7 | D6: =COUNTIFS(Findings!$B$2:$B$116,$A6,Findings!$K$2:$K$116,D$2) -> 2 | E6: =COUNTIFS(Findings!$B$2:$B$116,$A6,Findings!$K$2:$K$116,E$2) -> 0 | F6: =SUM(B6:E6) -> 11
A7: Total | B7: =SUM(B3:B6) -> 18 | C7: =SUM(C3:C6) -> 46 | D7: =SUM(D3:D6) -> 38 | E7: =SUM(E3:E6) -> 13 | F7: =SUM(F3:F6) -> 115
A9: Findings by theme x priority
B10: P0 | C10: P1 | D10: P2 | E10: P3 | F10: Total
A11: 1 Get it running | B11: =COUNTIFS(Findings!$C$2:$C$116,$A11,Findings!$K$2:$K$116,B$10) -> 7 | C11: =COUNTIFS(Findings!$C$2:$C$116,$A11,Findings!$K$2:$K$116,C$10) -> 6 | D11: =COUNTIFS(Findings!$C$2:$C$116,$A11,Findings!$K$2:$K$116,D$10) -> 3 | E11: =COUNTIFS(Findings!$C$2:$C$116,$A11,Findings!$K$2:$K$116,E$10) -> 0 | F11: =SUM(B11:E11) -> 16
A12: 2 Trust & control | B12: =COUNTIFS(Findings!$C$2:$C$116,$A12,Findings!$K$2:$K$116,B$10) -> 4 | C12: =COUNTIFS(Findings!$C$2:$C$116,$A12,Findings!$K$2:$K$116,C$10) -> 11 | D12: =COUNTIFS(Findings!$C$2:$C$116,$A12,Findings!$K$2:$K$116,D$10) -> 4 | E12: =COUNTIFS(Findings!$C$2:$C$116,$A12,Findings!$K$2:$K$116,E$10) -> 0 | F12: =SUM(B12:E12) -> 19
A13: 3 See what happened | B13: =COUNTIFS(Findings!$C$2:$C$116,$A13,Findings!$K$2:$K$116,B$10) -> 0 | C13: =COUNTIFS(Findings!$C$2:$C$116,$A13,Findings!$K$2:$K$116,C$10) -> 1 | D13: =COUNTIFS(Findings!$C$2:$C$116,$A13,Findings!$K$2:$K$116,D$10) -> 8 | E13: =COUNTIFS(Findings!$C$2:$C$116,$A13,Findings!$K$2:$K$116,E$10) -> 2 | F13: =SUM(B13:E13) -> 11
A14: 4 Do the work | B14: =COUNTIFS(Findings!$C$2:$C$116,$A14,Findings!$K$2:$K$116,B$10) -> 1 | C14: =COUNTIFS(Findings!$C$2:$C$116,$A14,Findings!$K$2:$K$116,C$10) -> 6 | D14: =COUNTIFS(Findings!$C$2:$C$116,$A14,Findings!$K$2:$K$116,D$10) -> 4 | E14: =COUNTIFS(Findings!$C$2:$C$116,$A14,Findings!$K$2:$K$116,E$10) -> 5 | F14: =SUM(B14:E14) -> 16
A15: 5 Find your way | B15: =COUNTIFS(Findings!$C$2:$C$116,$A15,Findings!$K$2:$K$116,B$10) -> 2 | C15: =COUNTIFS(Findings!$C$2:$C$116,$A15,Findings!$K$2:$K$116,C$10) -> 4 | D15: =COUNTIFS(Findings!$C$2:$C$116,$A15,Findings!$K$2:$K$116,D$10) -> 3 | E15: =COUNTIFS(Findings!$C$2:$C$116,$A15,Findings!$K$2:$K$116,E$10) -> 2 | F15: =SUM(B15:E15) -> 11
A16: 6 Reach & inclusion | B16: =COUNTIFS(Findings!$C$2:$C$116,$A16,Findings!$K$2:$K$116,B$10) -> 0 | C16: =COUNTIFS(Findings!$C$2:$C$116,$A16,Findings!$K$2:$K$116,C$10) -> 2 | D16: =COUNTIFS(Findings!$C$2:$C$116,$A16,Findings!$K$2:$K$116,D$10) -> 6 | E16: =COUNTIFS(Findings!$C$2:$C$116,$A16,Findings!$K$2:$K$116,E$10) -> 2 | F16: =SUM(B16:E16) -> 10
A17: 7 Extend it | B17: =COUNTIFS(Findings!$C$2:$C$116,$A17,Findings!$K$2:$K$116,B$10) -> 3 | C17: =COUNTIFS(Findings!$C$2:$C$116,$A17,Findings!$K$2:$K$116,C$10) -> 11 | D17: =COUNTIFS(Findings!$C$2:$C$116,$A17,Findings!$K$2:$K$116,D$10) -> 9 | E17: =COUNTIFS(Findings!$C$2:$C$116,$A17,Findings!$K$2:$K$116,E$10) -> 2 | F17: =SUM(B17:E17) -> 25
A18: 8 Build on it | B18: =COUNTIFS(Findings!$C$2:$C$116,$A18,Findings!$K$2:$K$116,B$10) -> 1 | C18: =COUNTIFS(Findings!$C$2:$C$116,$A18,Findings!$K$2:$K$116,C$10) -> 5 | D18: =COUNTIFS(Findings!$C$2:$C$116,$A18,Findings!$K$2:$K$116,D$10) -> 1 | E18: =COUNTIFS(Findings!$C$2:$C$116,$A18,Findings!$K$2:$K$116,E$10) -> 0 | F18: =SUM(B18:E18) -> 7
A19: Total | B19: =SUM(B11:B18) -> 18 | C19: =SUM(C11:C18) -> 46 | D19: =SUM(D11:D18) -> 38 | E19: =SUM(E11:E18) -> 13 | F19: =SUM(F11:F18) -> 115
A21: Verdict breakdown
A22: Verdict | B22: Count
A23: Confirmed | B23: =COUNTIF(Findings!$F$2:$F$116,$A23) -> 85
A24: Confirmed (duplicate) | B24: =COUNTIF(Findings!$F$2:$F$116,$A24) -> 8
A25: Partly true | B25: =COUNTIF(Findings!$F$2:$F$116,$A25) -> 11
A26: Overstated | B26: =COUNTIF(Findings!$F$2:$F$116,$A26) -> 2
A27: Asserted - not re-verified | B27: =COUNTIF(Findings!$F$2:$F$116,$A27) -> 9
A29: Competitive posture
A30: Posture | B30: Count
A31: Behind | B31: =COUNTIF(Findings!$L$2:$L$116,$A31) -> 86
A32: Level | B32: =COUNTIF(Findings!$L$2:$L$116,$A32) -> 19
A33: Uncontested | B33: =COUNTIF(Findings!$L$2:$L$116,$A33) -> 10

Sheet Merge map
A1: Dup group | B1: Merge into | C1: Also covered by | D1: One-line issue
A2: SETUP | B2: #28 | C2: #30, #32, #35 | D2: Setup finishes without ever proving the model works. Four rows, one fix.
A3: COST | B3: #18 | C3: #17, #37 | D3: Cost data already exists in the trajectory timeline; what is missing is a budget, a breakdown and a threshold alert.
A4: DOCTOR | B4: #38 | C4: #59 | D4: One diagnostic command covers both the pass/fail check and the bug-report bundle.
A5: I18N | B5: #62 | C5: #61 | D5: One backlog: move the 366 literals into the locale bundles and add a CI lint.
A6: REPLAY | B6: #76 | C6: #74, #83 | D6: Replay already shipped. The real defects are discoverability (#65) and the missing span waterfall — not the absence of replay.
A7: NOTIFY | B7: #52 | C7: #80 | D7: Web notification and desktop tray/toast are one feature with two surfaces.
A9: Net: 108 original rows -> 98 distinct issues; plus 7 added rows = 105 tracked issues.
A11: Adjacent but NOT duplicates - keep both
A12: Added row | B12: Looks like | C12: Why they are different
A13: #111 | B13: #25 | C13: #25 is the approval policy being off; #111 is the execution sandbox being opt-in and no folder-authorization step at setup.
A14: #112 | B14: #94 | C14: #94 is marketplace quality signals (ratings, downloads, freshness); #112 is a security audit run before a skill is allowed to execute.
A15: #114 | B15: #42 | C15: #42 is sharing skills between two of your own instances; #114 is accepting skills authored for another product.
A16: #115 | B16: #69 | C16: #69 is that mode names are meaningless; #115 is that the default mode is the wrong one for a first task.
A17: #110 | B17: #28 | C17: #28 is that setup never proves the model works; #110 is that a working key-less model already ships and is hidden.
